Workbook

Sheet 01_Historical_Data
A1: Particulars | B1: FY2025–26 Actual | C1: FY2024–25 Actual
A2: Revenue from operations | B2: 178650 | C2: 162990
A3: Employee benefit expenses | B3: 95094 | C3: 85950
A4: Total expenses | B4: 141688 | C4: 128982
A5: Profit before tax | B5: 39995 | C5: 37608
A6: Profit for the year | B6: 29474 | C6: 26750
A7: Salaries including bonus | B7: 90837 | C7: 82232
A8: Provident and other funds | B8: 2707 | C8: 2338
A9: Share-based payments | B9: 952 | C9: 802
A10: Staff welfare | B10: 598 | C10: 578
A11: Total employee expenses | B11: 95094 | C11: 85950

Sheet 06_Employee_Cost_Analysis
A1: Employee Expense | B1: FY2024–25 | C1: FY2025–26 | D1: Increase | E1: Growth % | F1: Contribution %
A2: Salaries including bonus | B2: 82232 | C2: 90837 | D2: =C2-B2 -> 8605 | E2: =D2/B2 -> 0.10464296 | F2: =D2/$D$6 -> 0.94105424
A3: Provident and other funds | B3: 2338 | C3: 2707 | D3: =C3-B3 -> 369 | E3: =D3/B3 -> 0.1578272 | F3: =D3/$D$6 -> 0.040354331
A4: Share-based payments | B4: 802 | C4: 952 | D4: =C4-B4 -> 150 | E4: =D4/B4 -> 0.18703242 | F4: =D4/$D$6 -> 0.016404199
A5: Staff welfare | B5: 578 | C5: 598 | D5: =C5-B5 -> 20 | E5: =D5/B5 -> 0.034602076 | F5: =D5/$D$6 -> 0.0021872266
A6: Total employee expenses | B6: 85950 | C6: 95094 | D6: =C6-B6 -> 9144 | E6: =D6/B6 -> 0.10638743 | F6: =D6/$D$6 -> 1
A9: Employee Cost as % of Revenue
A10: Financial Year | B10: Employee Expenses | C10: Revenue | D10: Employee Cost %
A11: FY2024–25 | B11: =B6 -> 85950 | C11: 162990 | D11: =B11/C11 -> 0.52733297
A12: FY2025–26 | B12: =C6 -> 95094 | C12: 178650 | D12: =B12/C12 -> 0.53229219
A15: Growth Comparison
A16: Revenue Growth | B16: =(C12-C11)/C11 -> 0.096079514
A17: Employee Expense Growth | B17: =(B12-B11)/B11 -> 0.10638743
A18: Difference in Growth Rates | B18: =B17-B16 -> 0.01030792
A21: Tax Analysis
A22: Metric | B22: FY2024–25 | C22: FY2025–26
A23: PBT | B23: 37608 | C23: 39995
A24: Tax Expense | B24: 10858 | C24: 10521
A25: PAT | B25: 26750 | C25: 29474
A26: Effective Tax Rate | B26: =B24/B23 -> 0.28871517 | C26: =C24/C23 -> 0.26305788
A28: Metric (₹ crore) | B28: FY2024–25 Actual | C28: FY2025–26 Actual | D28: Growth %
A29: Revenue from Operations | B29: 162990 | C29: 178650 | D29: =(C29-B29)/B29 -> 0.096079514
A30: Employee Benefit Expenses | B30: 85950 | C30: 95094 | D30: =(C30-B30)/B30 -> 0.10638743
A31: Technical Subcontractor Costs | B31: 12937 | C31: 15421 | D31: =(C31-B31)/B31 -> 0.19200742
A32: Software Package Costs | B32: 15911 | C32: 15722 | D32: =(C32-B32)/B32 -> -0.011878575
A33: Total Expenses | B33: 128982 | C33: 141688 | D33: =(C33-B33)/B33 -> 0.09850987

Sheet 03_Budget_Forecast
A1: Particulars | B1: FY2025–26 Actual | C1: FY2026–27 Budget | E1: Metric | F1: Assumption | G1: Reason | J1: Revenue and Employee Cost Sensitivity Analysis | S1: Cash Flow Forecast Assumptions
A2: Revenue from Operations | B2: 178650 | C2: =B2*(1+$F2) -> 192942 | E2: Revenue Growth % | F2: 0.08 | G2: Practice assumption; below historical growth of 9.6% | J2: Scenario | K2: Revenue Growth | L2: Forecast Revenue | M2: Forecast Employee Expenses | N2: Employee Expense Growth | O2: Adjusted Forecast PBT | P2: Adjusted PBT Margin | S2: Other investing cash flow | T2: 0
A3: Employee Benefit Expenses | B3: 95094 | C3: =B3*(1+$F3) -> 103652.46 | E3: Employee Expense Growth % | F3: 0.09 | G3: Practice assumption for employee cost increases | J3: Downside | K3: 0.05 | L3: =$B$2*(1+K3) -> 187582.5 | M3: =$B$3*(1+N3) -> 105554.34 | N3: 0.11 | O3: =L3+$C$11-$C$7-$C$12+($C$3-M3) -> 37740.9 | P3: =O3/L3 -> 0.20119627 | S3: Dividends | T3: 0
A4: Cost of Technical Sub-contractors | B4: 15421 | C4: =B4*(1+$F4) -> 16192.05 | E4: Technical Subcontractor Growth % | F4: 0.05 | G4: Practice assumption | J4: Base case | K4: 0.08 | L4: =$B$2*(1+K4) -> 192942 | M4: =$B$3*(1+N4) -> 103652.46 | N4: 0.09 | O4: =L4+$C$11-$C$7-$C$12+($C$3-M4) -> 45002.28 | P4: =O4/L4 -> 0.23324253 | S4: Share buybacks | T4: 0
A5: Cost of Software Packages | B5: 15722 | C5: =B5*(1+$F5) -> 16193.66 | E5: Software Package Cost Growth % | F5: 0.03 | G5: Practice assumption | J5: Upside | K5: 0.12 | L5: =$B$2*(1+K5) -> 200088 | M5: =$B$3*(1+N5) -> 102701.52 | N5: 0.08 | O5: =L5+$C$11-$C$7-$C$12+($C$3-M5) -> 53099.22 | P5: =O5/L5 -> 0.26537933 | S5: Other financing cash flow | T5: 0
A6: Other Expenses | B6: =B7-SUM(B3:B5) -> 15451 | C6: =B6*(1+$F6) -> 16223.55 | E6: Other Expenses Growth % | F6: 0.05 | G6: Practice assumption | S6: Foreign exchange impact | T6: 0
A7: Total Expenses | B7: 141688 | C7: =SUM(C3:C6) -> 152261.72 | E7: Depreciation & Amortization Growth % | F7: 0.05 | G7: Practice assumption
A8: Profit Before Tax (PBT) | B8: 39995 | C8: =C2+(B11*(1+$F$10))-C7-C12 -> 45002.28 | E8: Finance Cost Growth % | F8: 0 | G8: Assume no change
A9: Tax Expense | B9: 10521 | C9: =C8*$F$9 -> 11835.6 | E9: Effective Tax Rate | F9: 0.263 | G9: Based on FY2025–26 actual tax expense divided by PBT
A10: Profit After Tax (PAT) | B10: 29474 | C10: =C8-C9 -> 33166.68 | E10: Other Income Growth % | F10: 0 | G10: Assume no change
A11: Other Income, Net | B11: 4322 | C11: =B11*(1+$F$10) -> 4322 | E11: Dividend Growth % | F11: 0 | G11: Not needed for the P&L budget; optional for later cash-flow planning
A12: Exceptional Expense | B12: 1289 | C12: 0 | E12: Capital Expenditure Growth % | F12: 0.05 | G12: Practice assumption for later cash-flow forecasting
E13: Receivables Growth % | F13: 0.08 | G13: Practice assumption for working-capital forecasting
A14: PBT Margin % | C14: =C8/C2 -> 0.23324253
A15: PAT Margin % | C15: =C10/C2 -> 0.17189974
A16: Revenue Growth % | C16: =C2/B2-1 -> 0.08
A17: PAT Growth % | C17: =C10/B10-1 -> 0.12528603

Sheet 09_Integrated_Model
A1: Integrated Three-Statement Model
A2: Particulars | B2: FY2025-26 Actual | C2: FY2026-27 Forecast
A3: Net Profit After Tax | B3: ='03_Budget_Forecast'!B10 -> 29474 | C3: ='03_Budget_Forecast'!C10 -> 33166.68
A4: Add: Depreciation and Amortisation | B4: =('08_Cash_Flow'!C5) -> 4902 | C4: =B4*(1+'03_Budget_Forecast'!$F$7) -> 5147.1
A5: Change in Operating Working Capital | B5: -2650 | C5: =-(('07_Balance_Sheet'!E16+'07_Balance_Sheet'!E21-'07_Balance_Sheet'!E40-'07_Balance_Sheet'!E42-'07_Balance_Sheet'!E43)-'07_Balance_Sheet'!C100) -> -3650.8
A6: Other Operating Cash Adjustments (excluding tax) | B6: ='08_Cash_Flow'!C20-B3-B4-B5-'08_Cash_Flow'!C4 -> 387 | C6: =B6 -> 387
A7: Cash Flow from Operations | B7: ='08_Cash_Flow'!C22 -> 33986 | C7: =SUM(C3:C6) -> 35049.98
A8: Capital Expenditure | B8: 2727 | C8: 2863.35
A9: Free Cash Flow | B9: =B7-B8 -> 31259 | C9: =C7-C8 -> 32186.63
A10: Opening Cash and Cash Equivalents | B10: ='08_Cash_Flow'!C63 -> 24455 | C10: =B12 -> 22201
A11: Net Change in Cash | B11: ='08_Cash_Flow'!C61 -> -3854 | C11: =C12-C10 -> 28865.73
A12: Closing Cash and Cash Equivalents | B12: ='08_Cash_Flow'!C64 -> 22201 | C12: =C27 -> 51066.73
A13: Total Assets | B13: ='07_Balance_Sheet'!C23 -> 155967 | C13: ='07_Balance_Sheet'!E23 -> 189972
A14: Total Equity | B14: ='07_Balance_Sheet'!C31 -> 93297 | C14: ='07_Balance_Sheet'!E31 -> 126463.68
A15: Total Liabilities | B15: ='07_Balance_Sheet'!C46 -> 62670 | C15: ='07_Balance_Sheet'!E46 -> 63508.32
A16: Total Equity and Liabilities | B16: ='07_Balance_Sheet'!C47 -> 155967 | C16: =C14+C15 -> 189972
A17: Balance Sheet Check | B17: =B13-B16 -> 0 | C17: =C13-C16 -> 0
A19: Particulars | B19: FY2025-26 Actual | C19: FY2026-27 Forecast
A20: Capital expenditure | B20: 2727 | C20: 2863.35
A21: Other investing cash flow | C21: 0
A22: Dividends | C22: 0
A23: Share buybacks | C23: 0
A24: Other financing cash flow (balancing estimate; validate assumption) | C24: =('07_Balance_Sheet'!E47-('07_Balance_Sheet'!E14+SUM('07_Balance_Sheet'!E15:E16,'07_Balance_Sheet'!E18:E21)))-C10-(C7-C20+C21-C22-C23+C25) -> -3320.9
A25: Foreign exchange impact | B25: 1600 | C25: 0
A26: Net cash change from detailed flows | C26: =C7-C20+C21-C22-C23+C24+C25 -> 28865.73
A27: Closing cash from detailed flows | C27: =C10+C26 -> 51066.73

Sheet 04_Variance_Analysis
A1: Particulars | B1: FY2025–26 Actual | C1: FY2026–27 Forecast | D1: Forecast Change | E1: Forecast Change %
A2: Revenue from Operations | B2: ='03_Budget_Forecast'!B2 -> 178650 | C2: ='03_Budget_Forecast'!C2 -> 192942 | D2: =C2-B2 -> 14292 | E2: =IFERROR(D2/B2,0) -> 0.08
A3: Employee Benefit Expenses | B3: ='03_Budget_Forecast'!B3 -> 95094 | C3: ='03_Budget_Forecast'!C3 -> 103652.46 | D3: =C3-B3 -> 8558.46 | E3: =IFERROR(D3/B3,0) -> 0.09
A4: Technical Sub-contractors | B4: ='03_Budget_Forecast'!B4 -> 15421 | C4: ='03_Budget_Forecast'!C4 -> 16192.05 | D4: =C4-B4 -> 771.05 | E4: =IFERROR(D4/B4,0) -> 0.05
A5: Software Packages | B5: ='03_Budget_Forecast'!B5 -> 15722 | C5: ='03_Budget_Forecast'!C5 -> 16193.66 | D5: =C5-B5 -> 471.66 | E5: =IFERROR(D5/B5,0) -> 0.03
A6: Other Expenses | B6: ='03_Budget_Forecast'!B6 -> 15451 | C6: ='03_Budget_Forecast'!C6 -> 16223.55 | D6: =C6-B6 -> 772.55 | E6: =IFERROR(D6/B6,0) -> 0.05
A7: Total Expenses | B7: ='03_Budget_Forecast'!B7 -> 141688 | C7: ='03_Budget_Forecast'!C7 -> 152261.72 | D7: =C7-B7 -> 10573.72 | E7: =IFERROR(D7/B7,0) -> 0.074626786
A8: PBT | B8: ='03_Budget_Forecast'!B8 -> 39995 | C8: ='03_Budget_Forecast'!C8 -> 45002.28 | D8: =C8-B8 -> 5007.28 | E8: =IFERROR(D8/B8,0) -> 0.12519765
A9: Tax Expense | B9: ='03_Budget_Forecast'!B9 -> 10521 | C9: ='03_Budget_Forecast'!C9 -> 11835.6 | D9: =C9-B9 -> 1314.5996 | E9: =IFERROR(D9/B9,0) -> 0.12495007
A10: PAT | B10: ='03_Budget_Forecast'!B10 -> 29474 | C10: ='03_Budget_Forecast'!C10 -> 33166.68 | D10: =C10-B10 -> 3692.6804 | E10: =IFERROR(D10/B10,0) -> 0.12528603

Sheet 05_Management_Summary
A1: Infosys FP&A Management Summary
A3: Revenue grew by approximately 9.61% year over year.
A4: PBT margin declined by approximately 0.68 percentage points.
A5: PAT margin increased by approximately 0.09 percentage points.
A6: Further analysis is needed to identify the drivers of margin changes.
A8: Employee Cost Analysis — FY2025–26 **Key finding:** Total employee benefit expenses increased from ₹85,950 crore in FY2024–25 to ₹95,094 crore in FY2025–26, an increase of ₹9,144 crore (10.64%). **Primary driver:** Salaries including bonus increased by ₹8,605 crore and accounted for approximately 94.1% of the total employee expense increase. **Other observations:** Share-based payments recorded the highest percentage growth at approximately 18.70%, while staff welfare expenses grew by approximately 3.46%. **Recommended follow-up:** Investigate the impact of salary increments, changes in employee headcount, hiring, workforce utilization, and subcontractor usage to understand the underlying cost drivers. These are areas for investigation, not confirmed explanations from this analysis. **Management implication:** Employee costs grew faster than revenue growth of approximately 9.6%. FP&A should investigate whether this trend is putting pressure on operating margins and whether workforce productivity is improving sufficiently.
A10: **Tax and Profitability Analysis — FY2025–26** Infosys's effective tax rate decreased from approximately 28.87% in FY2024–25 to 26.31% in FY2025–26, a decline of approximately 2.56 percentage points. Tax expense decreased from ₹10,858 crore to ₹10,521 crore, while profit before tax increased from ₹37,608 crore to ₹39,995 crore. This contributed to PAT growing faster than PBT. Further analysis of the company's tax disclosures is required to identify the reasons for the lower effective tax rate.
A12: Working Capital & Liquidity
A13: Infosys's net working capital decreased from ₹54,249 crore in FY2024–25 to ₹51,167 crore in FY2025–26, a reduction of ₹3,082 crore. Current liabilities increased faster than current assets, while the current ratio declined from 2.27x to 1.98x. Management should investigate the drivers of higher current liabilities and assess the implications for liquidity and working capital efficiency.
A15: **Receivables & Unbilled Revenue:** The cash flow impact deteriorated by ₹3,408 crore in FY2025–26, creating additional pressure on operating cash flow. Further investigation is required to identify the underlying drivers.
A17: Cash Tax Payments: Cash taxes paid increased by ₹3,046 crore in FY2025–26, creating an additional cash outflow. This contributed to pressure on operating cash flow. Further analysis is required to understand the reasons for the increase.
A19: **Operating Cash Flow Analysis:** Operating cash flow declined by ₹1,708 crore in FY2025–26. Key adverse movements included receivables and unbilled revenue (₹3,408 crore), higher cash tax payments (₹3,046 crore), and loans and other assets (₹1,621 crore). These were partly offset by a favorable ₹2,887 crore movement in other financial liabilities, other liabilities and provisions. Further investigation is required to establish the underlying drivers.
... A31: Revenue and Expense Growth Analysis: Revenue increased by 9.61% in FY2025–26, while total expenses increased by 9.85%. Employee benefit expenses grew by 10.64%, and technical subcontractor costs grew by 19.20%, both exceeding revenue growth. In contrast, software package costs declined by 1.19%. Management should investigate the drivers of subcontractor cost growth and employee cost increases to assess their impact on operating margins. The analysis identifies areas for further investigation but does not establish the causes of the cost increases.

Sheet 08_Cash_Flow
A1: Infosys — Consolidated Cash Flow Statement
A2: Particulars | B2: FY2024–25 | C2: FY2025–26
A3: Profit for the year | B3: 26750 | C3: 29474
A4: Income tax expense | B4: 10858 | C4: 10521
A5: Depreciation and amortization | B5: 4812 | C5: 4902
A6: Interest and dividend income | B6: -2570 | C6: -2630
A7: Finance cost | B7: 416 | C7: 416
A8: Impairment loss under expected credit loss model | B8: 48 | C8: 33
A9: Exchange differences on translation of assets and liabilities | B9: 79 | C9: 954
A10: Stock compensation expense | B10: 802 | C10: 952
A11: Interest receivable on income tax refund | B11: -327 | C11: -63
A12: Provision for post-sale client support | B12: -110 | C12: -167
A13: Other adjustments | B13: 833 | C13: 881
A14: Changes in assets and liabilities
A15: Particulars | B15: FY2024–25 | C15: FY2025–26
A16: Trade receivables and unbilled revenue | B16: -1769 | C16: -5177
A17: Loans, other financial assets and other assets | B17: -1024 | C17: -2645
A18: Trade payables | B18: 176 | C18: -26
A19: Other financial liabilities, other liabilities and provisions | B19: 2322 | C19: 5209
A20: Cash generated from operations | B20: 41296 | C20: 42634
A21: Income taxes paid | B21: -5602 | C21: -8648
A22: Net cash generated by operating activities | B22: 35694 | C22: 33986
A23: Particulars | B23: FY2024–25 | C23: FY2025–26
A24: Cash flows from investing activities
A25: Expenditure on property, plant and equipment and intangibles, net of sale proceeds | B25: -2237 | C25: -2727
A26: Deposits placed with Corporation | B26: -1225 | C26: -944
A27: Redemption of deposits placed with Corporation | B27: 776 | C27: 725
A28: Interest and dividend received | B28: 2040 | C28: 2713
A29: Payment towards acquisition of business, net of cash acquired | B29: -3155 | C29: -637
A30: Payment of contingent consideration pertaining to acquisition of business | B30: 0 | C30: -13
A31: Escrow and other deposits pertaining to buyback | B31: 0 | C31: -1815
A32: Redemption of escrow and other deposits pertaining to buyback | B32: 0 | C32: 1815
A33: Other receipts | B33: 10 | C33: 15
A34: Payments to acquire investments — Tax-free bonds and government bonds | B34: -2 | C34: -153
A35: Payments to acquire investments — Mutual fund units | B35: -73048 | C35: -72878
A36: Payments to acquire investments — Certificates of deposit | B36: -6978 | C36: -14035
... A48: Net cash generated / (used in) from investing activities | B48: -1946 | C48: 1946
A49: Particulars | B49: FY2024–25 (₹ crore) | C49: FY2025–26 (₹ crore)
A50: Cash flows from Financing activities
A51: Payment of lease liabilities | B51: -2355 | C51: -2824
...

Sheet 02_Performance_Analysis
A1: Metric | B1: Value
A2: Revenue Growth % | B2: =IFERROR(('01_Historical_Data'!B2-'01_Historical_Data'!C2)/'01_Historical_Data'!C2,"Check data") -> 0.096079514
A3: Employee Expense Growth % | B3: =('01_Historical_Data'!B3-'01_Historical_Data'!C3)/'01_Historical_Data'!C3 -> 0.10638743
A4: Total Expense Growth % | B4: =('01_Historical_Data'!B4-'01_Historical_Data'!C4)/'01_Historical_Data'!C4 -> 0.09850987
A5: Profit Before Tax Growth % | B5: =('01_Historical_Data'!B5-'01_Historical_Data'!C5)/'01_Historical_Data'!C5 -> 0.063470538
A6: Profit for the Year Growth % | B6: =('01_Historical_Data'!B6-'01_Historical_Data'!C6)/'01_Historical_Data'!C6 -> 0.10183178
A8: Profitability Metrics
A9: PBT Margin — FY2025–26 | B9: ='01_Historical_Data'!B5/'01_Historical_Data'!B2 -> 0.2238735
A10: PBT Margin — FY2024–25 | B10: ='01_Historical_Data'!C5/'01_Historical_Data'!C2 -> 0.23073808
A11: PAT Margin — FY2025–26 | B11: ='01_Historical_Data'!B6/'01_Historical_Data'!B2 -> 0.16498181
A12: PAT Margin — FY2024–25 | B12: ='01_Historical_Data'!C6/'01_Historical_Data'!C2 -> 0.1641205
A14: Revenue Growth | B14: =B2 -> 0.096079514
A15: Employee Expense Growth | B15: =B3 -> 0.10638743
A16: Growth Difference | B16: =B15-B14 -> 0.01030792
A18: PBT Margin Change | B18: =B9-B10 -> -0.0068645864
A20: PAT Margin Change | B20: =B11-B12 -> 0.00086130981
A22: Metric | B22: FY2024–25 Actual | C22: FY2025–26 Actual | D22: FY2026–27 Forecast
A23: Revenue (₹ crore) | B23: 162990 | C23: 178650 | D23: 192942
A24: PBT (₹ crore) | B24: 37608 | C24: 39995 | D24: 45002.28
A25: PAT (₹ crore) | B25: 26750 | C25: 29474 | D25: 33166.68
A26: PBT Margin % | B26: =B24/B23 -> 0.23073808 | C26: =C24/C23 -> 0.2238735 | D26: =D24/D23 -> 0.23324253
A27: PAT Margin % | B27: =B25/B23 -> 0.1641205 | C27: =C25/C23 -> 0.16498181 | D27: =D25/D23 -> 0.17189974
A29: Metric (₹ crore) | B29: FY2024–25 | C29: FY2025–26
A30: Profit Before Tax (PBT) | B30: 37608 | C30: 39995
A31: Finance Cost | B31: 416 | C31: 416
A32: Depreciation & Amortization | B32: 4812 | C32: 4902
A33: Other Income, Net | B33: 3600 | C33: 4322
A34: EBITDA (calculated) | B34: =SUM(B30:B32)-B33 -> 39236 | C34: =SUM(C30:C32)-C33 -> 40991
A35: Revenue from Operations | B35: 162990 | C35: 178650
A36: EBITDA Margin | B36: =B34/B35 -> 0.24072642 | C36: =C34/C35 -> 0.22944864

Sheet 07_Balance_Sheet
A1: Assets
A2: Particulars | B2: FY2024–25 | C2: FY2025–26 | E2: FY2026-27 Forecast
A3: Property, plant and equipment | B3: 11778 | C3: 12651 | E3: =C3*(1+'03_Budget_Forecast'!$F$12) -> 13283.55
A4: Right-of-use assets | B4: 6311 | C4: 6177 | E4: =C4*(1+'03_Budget_Forecast'!$F$12) -> 6485.85
A5: Capital work-in-progress | B5: 814 | C5: 526 | E5: =C5*(1+'03_Budget_Forecast'!$F$12) -> 552.3
A6: Goodwill | B6: 10106 | C6: 12117 | E6: =C6 -> 12117
A7: Other intangible assets | B7: 2766 | C7: 2825 | E7: =C7*(1+'03_Budget_Forecast'!$F$7) -> 2966.25
A8: Non-current investments | B8: 11059 | C8: 8930 | E8: =C8 -> 8930
A9: Non-current loans | B9: 16 | C9: 6 | E9: =C9 -> 6
A10: Other non-current financial assets | B10: 3511 | C10: 2776 | E10: =C10 -> 2776
A11: Deferred tax assets (net) | B11: 1108 | C11: 2264 | E11: =C11 -> 2264
A12: Non-current income tax assets | B12: 1622 | C12: 666 | E12: =C12 -> 666
A13: Other non-current assets | B13: 2713 | C13: 3540 | E13: =C13 -> 3540
A14: Total non-current assets | B14: 51804 | C14: 52478 | E14: =SUM(E3:E13) -> 53586.95
A15: Current investments | B15: 12482 | C15: 12950 | E15: =C15 -> 12950
A16: Trade receivables | B16: 31158 | C16: 35234 | E16: =C16*(1+'03_Budget_Forecast'!$F$13) -> 38052.72
A17: Cash and cash equivalents | B17: 24455 | C17: 22201 | E17: ='09_Integrated_Model'!C12 -> 51066.73
A18: Current loans | B18: 249 | C18: 234 | E18: =C18 -> 234
A19: Other current financial assets | B19: 13840 | C19: 15890 | E19: =C19 -> 15890
A20: Current income tax assets | B20: 2975 | C20: 1835 | E20: =C20 -> 1835
A21: Other current assets | B21: 11940 | C21: 15145 | E21: =C21*(1+'03_Budget_Forecast'!$F$13) -> 16356.6
A22: Total current assets | B22: 97099 | C22: 103489 | E22: =SUM(E15:E21) -> 136385.05
A23: Total assets | B23: 148903 | C23: 155967 | E23: =E14+E22 -> 189972
A24: Equity & Liabilities
A25: Particulars | B25: FY2024–25 | C25: FY2025–26
A26: EQUITY
A27: Equity share capital | B27: 2073 | C27: 2024 | E27: =C27 -> 2024
A28: Other equity | B28: 93745 | C28: 90828 | E28: =C28+'09_Integrated_Model'!C3 -> 123994.68
A29: Total equity attributable to equity holders | B29: 95818 | C29: 92852 | E29: =SUM(E27:E28) -> 126018.68
A30: Non-controlling interests | B30: 385 | C30: 445 | E30: =C30 -> 445
A31: Total equity | B31: 96203 | C31: 93297 | E31: =SUM(E29:E30) -> 126463.68
A32: NON-CURRENT LIABILITIES
A33: Lease liabilities | B33: 5772 | C33: 6016 | E33: =C33*(1+'03_Budget_Forecast'!$F$12) -> 6316.8
A34: Other financial liabilities | B34: 2141 | C34: 2092 | E34: =C34 -> 2092
A35: Deferred tax liabilities (net) | B35: 1722 | C35: 1679 | E35: =C35 -> 1679
A36: Other non-current liabilities | B36: 215 | C36: 561 | E36: =C36 -> 561
A37: Total non-current liabilities | B37: 9850 | C37: 10348 | E37: =SUM(E33:E36) -> 10648.8
A38: CURRENT LIABILITIES
A39: Lease liabilities | B39: 2455 | C39: 3160 | E39: =C39*(1+'03_Budget_Forecast'!$F$12) -> 3318
A40: Trade payables | B40: 4164 | C40: 4744 | E40: =C40*(1+'03_Budget_Forecast'!$F$13) -> 5123.52
...

Sheet 10_Excel_Dashboard
A1: INFOSYS FINANCIAL PERFORMANCE DASHBOARD
A2: All financial figures in ₹ crore | FY25–FY26 Actuals | FY27 Forecast
A3: =C6 -> 178650 | C3: =C7 -> 29474 | E3: =C10 -> 0.16498181 | G3: =D6 -> 192942 | I3: =D7 -> 33166.68
A4: FY26 REVENUE | C4: FY26 NET PROFIT (PAT) | E4: FY26 NET PROFIT MARGIN | G4: FY27 FORECAST REVENUE | I4: FY27 FORECAST PAT
A5: Metric | B5: FY25 Actual | C5: FY26 Actual | D5: FY27 Forecast
A6: Revenue | B6: 162990 | C6: 178650 | D6: 192942
A7: Net Profit (PAT) | B7: 26750 | C7: 29474 | D7: 33166.68
A8: Operating Cash Flow | B8: 35694 | C8: 33986
A9: Revenue Growth | B9: =0 -> 0 | C9: =(C6-B6)/B6 -> 0.096079514 | D9: =(D6-C6)/C6 -> 0.08
A10: Net Profit Margin | B10: =B7/B6 -> 0.1641205 | C10: =C7/C6 -> 0.16498181 | D10: =D7/D6 -> 0.17189974

Sheet 11_DCF_Valuation
A2: Infosys — DCF Valuation Model
A3: Valuation Assumptions | B3: Value
A4: Risk-Free Rate | B4: 0.07
A5: Beta | B5: 1.2
A6: Equity Risk Premium | B6: 0.06
A7: Cost of Equity | B7: =B4+B5*B6 -> 0.142
A8: Cost of Debt | B8: 0.05
A9: Tax Rate | B9: 0.263
A10: Equity Weight | B10: 0.95
A11: Debt Weight | B11: =1-B10 -> 0.05
A12: WACC | B12: =B7*B10+B13*B11 -> 0.1367425
A13: After-Tax Cost of Debt | B13: =B8*(1-B9) -> 0.03685
A14: Metric | B14: FY27 | C14: FY28 | D14: FY29 | E14: FY30 | F14: FY31
A15: Revenue | B15: 192942 | C15: =B15*1.08 -> 208377.36 | D15: =C15*1.08 -> 225047.55 | E15: =D15*1.08 -> 243051.35 | F15: =E15*1.08 -> 262495.46
A16: EBIT | B16: =B15*20.3% -> 39167.226 | C16: =C15*20.3% -> 42300.604 | D16: =D15*20.3% -> 45684.652 | E16: =E15*20.3% -> 49339.425 | F16: =F15*20.3% -> 53286.579
A17: Tax on EBIT | B17: =B16*$B$9 -> 10300.98 | C17: =C16*$B$9 -> 11125.059 | D17: =D16*$B$9 -> 12015.064 | E17: =E16*$B$9 -> 12976.269 | F17: =F16*$B$9 -> 14014.37
A18: NOPAT | B18: =B16-B17 -> 28866.246 | C18: =C16-C17 -> 31175.545 | D18: =D16-D17 -> 33669.589 | E18: =E16-E17 -> 36363.156 | F18: =F16-F17 -> 39272.208
A19: Depreciation & Amortisation | B19: 5147.1 | C19: =B19*1.05 -> 5404.455 | D19: =C19*1.05 -> 5674.6778 | E19: =D19*1.05 -> 5958.4116 | F19: =E19*1.05 -> 6256.3322
A20: Capital Expenditure | B20: 2863.35 | C20: =B20*1.05 -> 3006.5175 | D20: =C20*1.05 -> 3156.8434 | E20: =D20*1.05 -> 3314.6855 | F20: =E20*1.05 -> 3480.4198
A21: Change in Net Working Capital | B21: 3650.8 | C21: =B21*1.08 -> 3942.864 | D21: =C21*1.08 -> 4258.2931 | E21: =D21*1.08 -> 4598.9566 | F21: =E21*1.08 -> 4966.8731
A22: Free Cash Flow to Firm (FCFF) | B22: =B18+B19-B20-B21 -> 27499.196 | C22: =C18+C19-C20-C21 -> 29630.619 | D22: =D18+D19-D20-D21 -> 31929.13 | E22: =E18+E19-E20-E21 -> 34407.925 | F22: =F18+F19-F20-F21 -> 37081.248
A23: Discount Period | B23: 1 | C23: 2 | D23: 3 | E23: 4 | F23: 5
A24: Discount Factor | B24: =1/(1+$B$12)^B23 -> 0.87970671 | C24: =1/(1+$B$12)^C23 -> 0.77388389 | D24: =1/(1+$B$12)^D23 -> 0.68079085 | E24: =1/(1+$B$12)^E23 -> 0.59889627 | F24: =1/(1+$B$12)^F23 -> 0.52685307
A25: Present Value of FCFF | B25: =B22*B24 -> 24191.227 | C25: =C22*C24 -> 22930.658 | D25: =D22*D24 -> 21737.059 | E25: =E22*E24 -> 20606.778 | F25: =F22*F24 -> 19536.369
A26: Terminal Value | B26: =F22*(1+$B$35)/($B$12-$B$35) -> 398630.36
A27: Present Value of Terminal Value | B27: =B26*F24 -> 210019.63
A28: Enterprise Value | B28: =SUM(B25:F25)+B27 -> 319021.72
A29: Less: Total Debt | B29: 0
A30: Add: Cash & Cash Equivalents | B30: 22201
A31: Equity Value | B31: =B28-B29+B30 -> 341222.72
A32: Shares Outstanding | B32: 404.694
A33: Implied Value per Share | B33: =B31/B32 -> 843.16229
A35: Terminal Growth Rate | B35: 0.04
A43: WACC / Terminal Growth | B43: 0.03 | C43: 0.035 | D43: 0.04 | E43: 0.045 | F43: 0.05
A44: 0.12 | B44: {=(SUMPRODUCT($B$22:$F$22,1/(1+$A44)^{1,2,3,4,5})+($F$22*(1+B$43)/($A44-B$43))/(1+$A44)^5+$B$30-$B$29)/$B$32} -> 931.10064 | C44: {=(SUMPRODUCT($B$22:$F$22,1/(1+$A44)^{1,2,3,4,5})+($F$22*(1+C$43)/($A44-C$43))/(1+$A44)^5+$B$30-$B$29)/$B$32} -> 969.16023 | D44: {=(SUMPRODUCT($B$22:$F$22,1/(1+$A44)^{1,2,3,4,5})+($F$22*(1+D$43)/($A44-D$43))/(1+$A44)^5+$B$30-$B$29)/$B$32} -> 1011.9773 | E44: {=(SUMPRODUCT($B$22:$F$22,1/(1+$A44)^{1,2,3,4,5})+($F$22*(1+E$43)/($A44-E$43))/(1+$A44)^5+$B$30-$B$29)/$B$32} -> 1060.5032 | F44: {=(SUMPRODUCT($B$22:$F$22,1/(1+$A44)^{1,2,3,4,5})+($F$22*(1+F$43)/($A44-F$43))/(1+$A44)^5+$B$30-$B$29)/$B$32} -> 1115.9615
A45: 0.13 | B45: {=(SUMPRODUCT($B$22:$F$22,1/(1+$A45)^{1,2,3,4,5})+($F$22*(1+B$43)/($A45-B$43))/(1+$A45)^5+$B$30-$B$29)/$B$32} -> 841.12797 | C45: {=(SUMPRODUCT($B$22:$F$22,1/(1+$A45)^{1,2,3,4,5})+($F$22*(1+C$43)/($A45-C$43))/(1+$A45)^5+$B$30-$B$29)/$B$32} -> 870.70538 | D45: {=(SUMPRODUCT($B$22:$F$22,1/(1+$A45)^{1,2,3,4,5})+($F$22*(1+D$43)/($A45-D$43))/(1+$A45)^5+$B$30-$B$29)/$B$32} -> 903.56918 | E45: {=(SUMPRODUCT($B$22:$F$22,1/(1+$A45)^{1,2,3,4,5})+($F$22*(1+E$43)/($A45-E$43))/(1+$A45)^5+$B$30-$B$29)/$B$32} -> 940.2993 | F45: {=(SUMPRODUCT($B$22:$F$22,1/(1+$A45)^{1,2,3,4,5})+($F$22*(1+F$43)/($A45-F$43))/(1+$A45)^5+$B$30-$B$29)/$B$32} -> 981.62069
A46: 0.1367 | B46: {=(SUMPRODUCT($B$22:$F$22,1/(1+$A46)^{1,2,3,4,5})+($F$22*(1+B$43)/($A46-B$43))/(1+$A46)^5+$B$30-$B$29)/$B$32} -> 790.32373 | C46: {=(SUMPRODUCT($B$22:$F$22,1/(1+$A46)^{1,2,3,4,5})+($F$22*(1+C$43)/($A46-C$43))/(1+$A46)^5+$B$30-$B$29)/$B$32} -> 815.61256 | D46: {=(SUMPRODUCT($B$22:$F$22,1/(1+$A46)^{1,2,3,4,5})+($F$22*(1+D$43)/($A46-D$43))/(1+$A46)^5+$B$30-$B$29)/$B$32} -> 843.51658 | E46: {=(SUMPRODUCT($B$22:$F$22,1/(1+$A46)^{1,2,3,4,5})+($F$22*(1+E$43)/($A46-E$43))/(1+$A46)^5+$B$30-$B$29)/$B$32} -> 874.46356 | F46: {=(SUMPRODUCT($B$22:$F$22,1/(1+$A46)^{1,2,3,4,5})+($F$22*(1+F$43)/($A46-F$43))/(1+$A46)^5+$B$30-$B$29)/$B$32} -> 908.97998
A47: 0.14 | B47: {=(SUMPRODUCT($B$22:$F$22,1/(1+$A47)^{1,2,3,4,5})+($F$22*(1+B$43)/($A47-B$43))/(1+$A47)^5+$B$30-$B$29)/$B$32} -> 767.58737 | C47: {=(SUMPRODUCT($B$22:$F$22,1/(1+$A47)^{1,2,3,4,5})+($F$22*(1+C$43)/($A47-C$43))/(1+$A47)^5+$B$30-$B$29)/$B$32} -> 791.07267 | D47: {=(SUMPRODUCT($B$22:$F$22,1/(1+$A47)^{1,2,3,4,5})+($F$22*(1+D$43)/($A47-D$43))/(1+$A47)^5+$B$30-$B$29)/$B$32} -> 816.90651 | E47: {=(SUMPRODUCT($B$22:$F$22,1/(1+$A47)^{1,2,3,4,5})+($F$22*(1+E$43)/($A47-E$43))/(1+$A47)^5+$B$30-$B$29)/$B$32} -> 845.45969 | F47: {=(SUMPRODUCT($B$22:$F$22,1/(1+$A47)^{1,2,3,4,5})+($F$22*(1+F$43)/($A47-F$43))/(1+$A47)^5+$B$30-$B$29)/$B$32} -> 877.18545
A48: 0.15 | B48: {=(SUMPRODUCT($B$22:$F$22,1/(1+$A48)^{1,2,3,4,5})+($F$22*(1+B$43)/($A48-B$43))/(1+$A48)^5+$B$30-$B$29)/$B$32} -> 706.3678 | C48: {=(SUMPRODUCT($B$22:$F$22,1/(1+$A48)^{1,2,3,4,5})+($F$22*(1+C$43)/($A48-C$43))/(1+$A48)^5+$B$30-$B$29)/$B$32} -> 725.34915 | D48: {=(SUMPRODUCT($B$22:$F$22,1/(1+$A48)^{1,2,3,4,5})+($F$22*(1+D$43)/($A48-D$43))/(1+$A48)^5+$B$30-$B$29)/$B$32} -> 746.05608 | E48: {=(SUMPRODUCT($B$22:$F$22,1/(1+$A48)^{1,2,3,4,5})+($F$22*(1+E$43)/($A48-E$43))/(1+$A48)^5+$B$30-$B$29)/$B$32} -> 768.7351 | F48: {=(SUMPRODUCT($B$22:$F$22,1/(1+$A48)^{1,2,3,4,5})+($F$22*(1+F$43)/($A48-F$43))/(1+$A48)^5+$B$30-$B$29)/$B$32} -> 793.68202
